TASK [ios_eigrp4 : enable eigrp4 interfaces] ***********************************
Wednesday 20 May 2020  16:29:07 +0200 (0:00:04.238)       0:07:09.121 *********
An exception occurred during task execution. To see the full traceback, use -vvv. The error was: R1(config-router)#
failed: [R1] (item={u'ipv4_address': u'dhcp', u'passive': None, u'description': u'Internet connexion ip nat outside', u'eigrp4': None, u'id': u'GigabitEthernet0/0', u'rip': None}) => {"ansible_loop_var": "item", "changed": false, "item": {"description": "Internet connexion ip nat outside", "eigrp4": null, "id": "GigabitEthernet0/0", "ipv4_address": "dhcp", "passive": null, "rip": null}, "module_stderr": "Traceback (most recent call last):\n  File \"/root/.ansible/tmp/ansible-local-3171KYlFS4/ansible-tmp-1589984949.37-12660-140350744314363/AnsiballZ_ios_config.py\", line 102, in <module>\n    _ansiballz_main()\n  File \"/root/.ansible/tmp/ansible-local-3171KYlFS4/ansible-tmp-1589984949.37-12660-140350744314363/AnsiballZ_ios_config.py\", line 94, in _ansiballz_main\n    invoke_module(zipped_mod, temp_path, ANSIBALLZ_PARAMS)\n  File \"/root/.ansible/tmp/ansible-local-3171KYlFS4/ansible-tmp-1589984949.37-12660-140350744314363/AnsiballZ_ios_config.py\", line 40, in invoke_module\n    runpy.run_module(mod_name='ansible.modules.network.ios.ios_config', init_globals=None, run_name='__main__', alter_sys=True)\n  File \"/usr/lib64/python2.7/runpy.py\", line 176, in run_module\n    fname, loader, pkg_name)\n  File \"/usr/lib64/python2.7/runpy.py\", line 82, in _run_module_code\n    mod_name, mod_fname, mod_loader, pkg_name)\n  File \"/usr/lib64/python2.7/runpy.py\", line 72, in _run_code\n    exec code in run_globals\n  File \"/tmp/ansible_ios_config_payload_qvdjgC/ansible_ios_config_payload.zip/ansible/modules/network/ios/ios_config.py\", line 569, in <module>\n  File \"/tmp/ansible_ios_config_payload_qvdjgC/ansible_ios_config_payload.zip/ansible/modules/network/ios/ios_config.py\", line 500, in main\n  File \"/tmp/ansible_ios_config_payload_qvdjgC/ansible_ios_config_payload.zip/ansible/modules/network/ios/ios_config.py\", line 364, in edit_config_or_macro\n  File \"/tmp/ansible_ios_config_payload_qvdjgC/ansible_ios_config_payload.zip/ansible/module_utils/connection.py\", line 185, in __rpc__\nansible.module_utils.connection.ConnectionError: network False 0.0.0.0\r\nnetwork False 0.0.0.0\r\n        ^\r\n% Invalid input detected at '^' marker.\r\n\r\nR1(config-router)#\n", "module_stdout": "", "msg": "MODULE FAILURE\nSee stdout/stderr for the exact error", "rc": 1}
An exception occurred during task execution. To see the full traceback, use -vvv. The error was: R2(config-router)#
failed: [R2] (item={u'ipv4_address': None, u'passive': None, u'description': u'LAN R2', u'eigrp4': None, u'id': u'GigabitEthernet0/0', u'rip': None}) => {"ansible_loop_var": "item", "changed": false, "item": {"description": "LAN R2", "eigrp4": null, "id": "GigabitEthernet0/0", "ipv4_address": null, "passive": null, "rip": null}, "module_stderr": "Traceback (most recent call last):\n  File \"/root/.ansible/tmp/ansible-local-3171KYlFS4/ansible-tmp-1589984949.4-12661-86925775192803/AnsiballZ_ios_config.py\", line 102, in <module>\n    _ansiballz_main()\n  File \"/root/.ansible/tmp/ansible-local-3171KYlFS4/ansible-tmp-1589984949.4-12661-86925775192803/AnsiballZ_ios_config.py\", line 94, in _ansiballz_main\n    invoke_module(zipped_mod, temp_path, ANSIBALLZ_PARAMS)\n  File \"/root/.ansible/tmp/ansible-local-3171KYlFS4/ansible-tmp-1589984949.4-12661-86925775192803/AnsiballZ_ios_config.py\", line 40, in invoke_module\n    runpy.run_module(mod_name='ansible.modules.network.ios.ios_config', init_globals=None, run_name='__main__', alter_sys=True)\n  File \"/usr/lib64/python2.7/runpy.py\", line 176, in run_module\n    fname, loader, pkg_name)\n  File \"/usr/lib64/python2.7/runpy.py\", line 82, in _run_module_code\n    mod_name, mod_fname, mod_loader, pkg_name)\n  File \"/usr/lib64/python2.7/runpy.py\", line 72, in _run_code\n    exec code in run_globals\n  File \"/tmp/ansible_ios_config_payload_ZfxxOh/ansible_ios_config_payload.zip/ansible/modules/network/ios/ios_config.py\", line 569, in <module>\n  File \"/tmp/ansible_ios_config_payload_ZfxxOh/ansible_ios_config_payload.zip/ansible/modules/network/ios/ios_config.py\", line 500, in main\n  File \"/tmp/ansible_ios_config_payload_ZfxxOh/ansible_ios_config_payload.zip/ansible/modules/network/ios/ios_config.py\", line 364, in edit_config_or_macro\n  File \"/tmp/ansible_ios_config_payload_ZfxxOh/ansible_ios_config_payload.zip/ansible/module_utils/connection.py\", line 185, in __rpc__\nansible.module_utils.connection.ConnectionError: network False 0.0.0.0\r\nnetwork False 0.0.0.0\r\n        ^\r\n% Invalid input detected at '^' marker.\r\n\r\nR2(config-router)#\n", "module_stdout": "", "msg": "MODULE FAILURE\nSee stdout/stderr for the exact error", "rc": 1}
An exception occurred during task execution. To see the full traceback, use -vvv. The error was: R3(config-router)#
failed: [R3] (item={u'ipv4_address': None, u'passive': None, u'description': u'LAN R3', u'eigrp4': None, u'id': u'GigabitEthernet0/0', u'rip': None}) => {"ansible_loop_var": "item", "changed": false, "item": {"description": "LAN R3", "eigrp4": null, "id": "GigabitEthernet0/0", "ipv4_address": null, "passive": null, "rip": null}, "module_stderr": "Traceback (most recent call last):\n  File \"/root/.ansible/tmp/ansible-local-3171KYlFS4/ansible-tmp-1589984949.44-12662-99931148419048/AnsiballZ_ios_config.py\", line 102, in <module>\n    _ansiballz_main()\n  File \"/root/.ansible/tmp/ansible-local-3171KYlFS4/ansible-tmp-1589984949.44-12662-99931148419048/AnsiballZ_ios_config.py\", line 94, in _ansiballz_main\n    invoke_module(zipped_mod, temp_path, ANSIBALLZ_PARAMS)\n  File \"/root/.ansible/tmp/ansible-local-3171KYlFS4/ansible-tmp-1589984949.44-12662-99931148419048/AnsiballZ_ios_config.py\", line 40, in invoke_module\n    runpy.run_module(mod_name='ansible.modules.network.ios.ios_config', init_globals=None, run_name='__main__', alter_sys=True)\n  File \"/usr/lib64/python2.7/runpy.py\", line 176, in run_module\n    fname, loader, pkg_name)\n  File \"/usr/lib64/python2.7/runpy.py\", line 82, in _run_module_code\n    mod_name, mod_fname, mod_loader, pkg_name)\n  File \"/usr/lib64/python2.7/runpy.py\", line 72, in _run_code\n    exec code in run_globals\n  File \"/tmp/ansible_ios_config_payload_5EJA3u/ansible_ios_config_payload.zip/ansible/modules/network/ios/ios_config.py\", line 569, in <module>\n  File \"/tmp/ansible_ios_config_payload_5EJA3u/ansible_ios_config_payload.zip/ansible/modules/network/ios/ios_config.py\", line 500, in main\n  File \"/tmp/ansible_ios_config_payload_5EJA3u/ansible_ios_config_payload.zip/ansible/modules/network/ios/ios_config.py\", line 364, in edit_config_or_macro\n  File \"/tmp/ansible_ios_config_payload_5EJA3u/ansible_ios_config_payload.zip/ansible/module_utils/connection.py\", line 185, in __rpc__\nansible.module_utils.connection.ConnectionError: network False 0.0.0.0\r\nnetwork False 0.0.0.0\r\n        ^\r\n% Invalid input detected at '^' marker.\r\n\r\nR3(config-router)#\n", "module_stdout": "", "msg": "MODULE FAILURE\nSee stdout/stderr for the exact error", "rc": 1}
failed: [R1] (item={u'ipv4_address': u'10.1.1.1/24', u'id': u'GigabitEthernet0/2', u'description': u'Link to R2', u'rip': None, u'eigrp4': None}) => {"ansible_loop_var": "item", "changed": false, "item": {"description": "Link to R2", "eigrp4": null, "id": "GigabitEthernet0/2", "ipv4_address": "10.1.1.1/24", "rip": null}, "msg": "show version\r\nshow version\r\n  ^\r\n% Invalid input detected at '^' marker.\r\n\r\nR1(config-router)#"}
failed: [R2] (item={u'ipv4_address': u'10.1.1.2/24', u'id': u'GigabitEthernet0/1', u'description': u'Link to R1 on port Gi0/2', u'rip': None, u'eigrp4': None}) => {"ansible_loop_var": "item", "changed": false, "item": {"description": "Link to R1 on port Gi0/2", "eigrp4": null, "id": "GigabitEthernet0/1", "ipv4_address": "10.1.1.2/24", "rip": null}, "msg": "show version\r\nshow version\r\n  ^\r\n% Invalid input detected at '^' marker.\r\n\r\nR2(config-router)#"}
failed: [R3] (item={u'ipv4_address': u'10.1.2.3/24', u'id': u'GigabitEthernet0/1', u'description': u'Link to R1', u'rip': None, u'eigrp4': None}) => {"ansible_loop_var": "item", "changed": false, "item": {"description": "Link to R1", "eigrp4": null, "id": "GigabitEthernet0/1", "ipv4_address": "10.1.2.3/24", "rip": null}, "msg": "show version\r\nshow version\r\n  ^\r\n% Invalid input detected at '^' marker.\r\n\r\nR3(config-router)#"}
failed: [R1] (item={u'ipv4_address': u'10.1.2.1/24', u'id': u'GigabitEthernet0/3', u'description': u'Link to R3', u'rip': None, u'eigrp4': None}) => {"ansible_loop_var": "item", "changed": false, "item": {"description": "Link to R3", "eigrp4": null, "id": "GigabitEthernet0/3", "ipv4_address": "10.1.2.1/24", "rip": null}, "msg": "show version\r\nshow version\r\n  ^\r\n% Invalid input detected at '^' marker.\r\n\r\nR1(config-router)#"}
failed: [R2] (item={u'ipv4_address': u'10.1.3.2/24', u'id': u'GigabitEthernet0/3', u'description': u'Link to R3 on port G0/2', u'rip': None, u'eigrp4': None}) => {"ansible_loop_var": "item", "changed": false, "item": {"description": "Link to R3 on port G0/2", "eigrp4": null, "id": "GigabitEthernet0/3", "ipv4_address": "10.1.3.2/24", "rip": null}, "msg": "show version\r\nshow version\r\n  ^\r\n% Invalid input detected at '^' marker.\r\n\r\nR2(config-router)#"}
failed: [R3] (item={u'ipv4_address': u'10.1.3.3/24', u'id': u'GigabitEthernet0/2', u'description': u'Link to R2', u'rip': None, u'eigrp4': None}) => {"ansible_loop_var": "item", "changed": false, "item": {"description": "Link to R2", "eigrp4": null, "id": "GigabitEthernet0/2", "ipv4_address": "10.1.3.3/24", "rip": null}, "msg": "show version\r\nshow version\r\n  ^\r\n% Invalid input detected at '^' marker.\r\n\r\nR3(config-router)#"}
failed: [R2] (item={u'ipv4_address': u'10.2.1.2/24', u'id': u'GigabitEthernet0/2', u'description': u'Link to DS1 on port Gi2/0', u'rip': None, u'eigrp4': None}) => {"ansible_loop_var": "item", "changed": false, "item": {"description": "Link to DS1 on port Gi2/0", "eigrp4": null, "id": "GigabitEthernet0/2", "ipv4_address": "10.2.1.2/24", "rip": null}, "msg": "show version\r\nshow version\r\n  ^\r\n% Invalid input detected at '^' marker.\r\n\r\nR2(config-router)#"}
failed: [R3] (item={u'ipv4_address': u'10.3.1.3/24', u'id': u'GigabitEthernet0/3', u'description': u'Link to DS2', u'rip': None, u'eigrp4': None}) => {"ansible_loop_var": "item", "changed": false, "item": {"description": "Link to DS2", "eigrp4": null, "id": "GigabitEthernet0/3", "ipv4_address": "10.3.1.3/24", "rip": null}, "msg": "show version\r\nshow version\r\n  ^\r\n% Invalid input detected at '^' marker.\r\n\r\nR3(config-router)#"}
failed: [R2] (item={u'ipv4_address': u'10.2.2.2/24', u'id': u'GigabitEthernet0/4', u'description': u'Link to DS1 on port Gi3/0', u'rip': None, u'eigrp4': None}) => {"ansible_loop_var": "item", "changed": false, "item": {"description": "Link to DS1 on port Gi3/0", "eigrp4": null, "id": "GigabitEthernet0/4", "ipv4_address": "10.2.2.2/24", "rip": null}, "msg": "show version\r\nshow version\r\n  ^\r\n% Invalid input detected at '^' marker.\r\n\r\nR2(config-router)#"}
failed: [R3] (item={u'ipv4_address': u'10.3.2.3/24', u'id': u'GigabitEthernet0/4', u'description': u'Link to DS2', u'rip': None, u'eigrp4': None}) => {"ansible_loop_var": "item", "changed": false, "item": {"description": "Link to DS2", "eigrp4": null, "id": "GigabitEthernet0/4", "ipv4_address": "10.3.2.3/24", "rip": null}, "msg": "show version\r\nshow version\r\n  ^\r\n% Invalid input detected at '^' marker.\r\n\r\nR3(config-router)#"}
failed: [R2] (item={u'ipv4_address': u'10.2.3.2/24', u'id': u'GigabitEthernet0/5', u'description': u'Link to DS2 on port Gi2/1', u'rip': None, u'eigrp4': None}) => {"ansible_loop_var": "item", "changed": false, "item": {"description": "Link to DS2 on port Gi2/1", "eigrp4": null, "id": "GigabitEthernet0/5", "ipv4_address": "10.2.3.2/24", "rip": null}, "msg": "show version\r\nshow version\r\n  ^\r\n% Invalid input detected at '^' marker.\r\n\r\nR2(config-router)#"}
failed: [R3] (item={u'ipv4_address': u'10.3.3.3/24', u'id': u'GigabitEthernet0/5', u'description': u'Link to DS1', u'rip': None, u'eigrp4': None}) => {"ansible_loop_var": "item", "changed": false, "item": {"description": "Link to DS1", "eigrp4": null, "id": "GigabitEthernet0/5", "ipv4_address": "10.3.3.3/24", "rip": null}, "msg": "show version\r\nshow version\r\n  ^\r\n% Invalid input detected at '^' marker.\r\n\r\nR3(config-router)#"}
failed: [R2] (item={u'ipv4_address': u'10.2.4.2/24', u'id': u'GigabitEthernet0/6', u'description': u'Link to DS2 on port 3/1', u'rip': None, u'eigrp4': None}) => {"ansible_loop_var": "item", "changed": false, "item": {"description": "Link to DS2 on port 3/1", "eigrp4": null, "id": "GigabitEthernet0/6", "ipv4_address": "10.2.4.2/24", "rip": null}, "msg": "show version\r\nshow version\r\n  ^\r\n% Invalid input detected at '^' marker.\r\n\r\nR2(config-router)#"}
failed: [R3] (item={u'ipv4_address': u'10.3.4.3/24', u'id': u'GigabitEthernet0/6', u'description': u'Link to DS1', u'rip': None, u'eigrp4': None}) => {"ansible_loop_var": "item", "changed": false, "item": {"description": "Link to DS1", "eigrp4": null, "id": "GigabitEthernet0/6", "ipv4_address": "10.3.4.3/24", "rip": null}, "msg": "show version\r\nshow version\r\n  ^\r\n% Invalid input detected at '^' marker.\r\n\r\nR3(config-router)#"}
